Workbook
Name Slicer_Delivery_Status: #N/A
Name Slicer_Order_Month1: #N/A
Name Slicer_Payment_Method: #N/A
Name Slicer_Region: #N/A

Sheet Dahboard

Sheet Sheet1

Sheet Pivot table
A1: Delivery Status | B1: (Multiple Items) | I1: Cancellation Rate by Region
A2: Payment Method | B2: (All) | I2: Row Labels | J2: Sum of Cancellation Rate by Region | N2: Cleaned Delivery Status | O2: (Multiple Items)
I3: Central | J3: 0.35714286 | N3: Total Revenue
A4: Region | B4: Sum of Total Amount | I4: East | J4: 0.16666667 | N4: Sum of Total Amount
A5: West | B5: 6921 | I5: North | J5: 0.4 | N5: 28297
A6: North | B6: 7030 | I6: South | J6: 0.2
A7: South | B7: 6779 | I7: West | J7: 0.34782609
A8: East | B8: 3353 | I8: Grand Total | J8: 0.3 | N8: % of Fast Deliveries
A9: Central | B9: 4214 | N9: Sum of Field1
A10: Grand Total | B10: 28297 | N10: 0.32352941
A12: Total Sales Amount by Region
N13: Top 3 Performing Regions
N14: Cleaned Delivery Status | O14: (Multiple Items)
A16: Count of Orders by Delivery Status | I16: Total Sales Amount by Product Category | N16: Row Labels | O16: Sum of Total Amount
A17: Payment Method | B17: (All) | I17: Payment Method | J17: (All) | N17: North | O17: 7030
A18: Category | B18: (All) | I18: Cleaned Delivery Status | J18: (Multiple Items) | N18: West | O18: 6921
N19: South | O19: 6779
A20: Row Labels | B20: Count of Order ID | I20: Row Labels | J20: Sum of Total Amount | N20: Central | O20: 4214
A21: Cancelled | B21: 30 | I21: Electronics | J21: 13035 | N21: East | O21: 3353
A22: Delivered | B22: 34 | I22: Fashion | J22: 2425 | N22: Grand Total | O22: 28297
A23: In Transit | B23: 36 | I23: Home | J23: 8450
A24: Grand Total | B24: 100 | I24: Toys | J24: 2989
I25: Books | J25: 1398 | N25: Cleaned Delivery Status | O25: (Multiple Items)
I26: Grand Total | J26: 28297 | N26: Highest-selling Product
N27: Row Labels | O27: Sum of Total Amount
N28: Smartphone | O28: 9644
A29: Average Delivery Time | N29: Grand Total | O29: 9644
A30: Payment Method | B30: (All)
A31: Category | B31: (All)
A33: Average of Delivery Days
A34: 3.7647059
A37: Sales Amount for Delivered Orders only
A38: Sum of Effective Sales
A39: 13656

Sheet AmazonSales
A1: Order ID | B1: Order Date | C1: Delivery Date | D1: Cancel Date | E1: Order Month | F1: Delivery Status | G1: Customer ID | H1: Product ID | I1: Region | J1: Sale Price/Unit | K1: Quantity | L1: Total Amount | M1: Payment Method | N1: Fulfillment Partner | O1: Coustmer Name | P1: Product Name | Q1: Product Category | R1: Delivery Performance | S1: Regional Target | T1: Column1 | U1: Cancellation Count | V1: Oder Count | W1: Fat Delivery | X1: Deliverd
A2: ORD0001 | B2: 45291 | D2: 45293 | E2: =TEXT(tbl_sale[[#This Row],[Order Date]],"MMM") -> Dec | F2: =IF(D2<>"","Cancelled",IF(C2<>"","Delivered","In Transit")) -> Cancelled | G2: CUST021 | H2: PROD012 | I2: North | J2: 44 | K2: 1 | L2: 44 | M2: Apple Pay | N2: DHL | O2: =_xlfn.XLOOKUP(tbl_sale[[#This Row],[Customer ID]],CustomerMaster!A:A,CustomerMaster!B:B,"NA",0) -> Zoe Mitchell | P2: =_xlfn.XLOOKUP(tbl_sale[[#This Row],[Product ID]],ProductMaster!$A$2:$A$23,ProductMaster!$B$2:$B$23,"NA",0) -> Lamp | Q2: =_xlfn.XLOOKUP(tbl_sale[[#This Row],[Product ID]],ProductMaster!$A$2:$A$23,ProductMaster!$C$2:$C$23,"NA",0) -> Home | R2: =IFERROR(IF(tbl_sale[[#This Row],[Delivery Date]]="","Pending",IF(tbl_sale[[#This Row],[Delivery Date]]-tbl_sale[[#This Row],[Order Date]]<= 2,"Fast","Slow")),"Error") -> Pending | S2: =_xlfn.XLOOKUP(tbl_sale[[#This Row],[Region]],RegionGoals!$A$2:$A$6,RegionGoals!$B$2:$B$6, ,0) -> 105000 | T2: =_xlfn.XLOOKUP(tbl_sale[[#This Row],[Customer ID]],CustomerMaster!$A:$A,CustomerMaster!$C:$C,"NA",0) -> Individual | U2: =IF(tbl_sale[[#This Row],[Delivery Status]]="Cancelled",1,0) -> 1 | V2: =IF(tbl_sale[[#This Row],[Order ID]]<>"",1,0) -> 1 | W2: =IF(AND(tbl_sale[[#This Row],[Delivery Status]]="Delivered",tbl_sale[[#This Row],[Delivery Performance]]="Fast"),1,0) -> 0 | X2: =IF(tbl_sale[[#This Row],[Delivery Status]]="Delivered",1,0) -> 0
A3: ORD0002 | B3: 44979 | C3: 44981 | E3: =TEXT(tbl_sale[[#This Row],[Order Date]],"MMM") -> Feb | F3: =IF(D3<>"","Cancelled",IF(C3<>"","Delivered","In Transit")) -> Delivered | G3: CUST029 | H3: PROD018 | I3: East | J3: 96 | K3: 4 | L3: 384 | M3: Credit Card | N3: DHL | O3: =_xlfn.XLOOKUP(tbl_sale[[#This Row],[Customer ID]],CustomerMaster!A:A,CustomerMaster!B:B,"NA",0) -> Ava White | P3: =_xlfn.XLOOKUP(tbl_sale[[#This Row],[Product ID]],ProductMaster!$A$2:$A$23,ProductMaster!$B$2:$B$23,"NA",0) -> Doll House | Q3: =_xlfn.XLOOKUP(tbl_sale[[#This Row],[Product ID]],ProductMaster!$A$2:$A$23,ProductMaster!$C$2:$C$23,"NA",0) -> Toys | R3: =IFERROR(IF(tbl_sale[[#This Row],[Delivery Date]]="","Pending",IF(tbl_sale[[#This Row],[Delivery Date]]-tbl_sale[[#This Row],[Order Date]]<= 2,"Fast","Slow")),"Error") -> Fast | S3: =_xlfn.XLOOKUP(tbl_sale[[#This Row],[Region]],RegionGoals!$A$2:$A$6,RegionGoals!$B$2:$B$6, ,0) -> 50500 | T3: =_xlfn.XLOOKUP(tbl_sale[[#This Row],[Customer ID]],CustomerMaster!$A:$A,CustomerMaster!$C:$C,"NA",0) -> Individual | U3: =IF(tbl_sale[[#This Row],[Delivery Status]]="Cancelled",1,0) -> 0 | V3: =IF(tbl_sale[[#This Row],[Order ID]]<>"",1,0) -> 1 | W3: =IF(AND(tbl_sale[[#This Row],[Delivery Status]]="Delivered",tbl_sale[[#This Row],[Delivery Performance]]="Fast"),1,0) -> 1 | X3: =IF(tbl_sale[[#This Row],[Delivery Status]]="Delivered",1,0) -> 1
A4: ORD0003 | B4: 45210 | E4: =TEXT(tbl_sale[[#This Row],[Order Date]],"MMM") -> Oct | F4: =IF(D4<>"","Cancelled",IF(C4<>"","Delivered","In Transit")) -> In Transit | G4: CUST021 | H4: PROD013 | I4: South | J4: 194 | K4: 4 | L4: 776 | M4: Credit Card | N4: USPS | O4: =_xlfn.XLOOKUP(tbl_sale[[#This Row],[Customer ID]],CustomerMaster!A:A,CustomerMaster!B:B,"NA",0) -> Zoe Mitchell | P4: =_xlfn.XLOOKUP(tbl_sale[[#This Row],[Product ID]],ProductMaster!$A$2:$A$23,ProductMaster!$B$2:$B$23,"NA",0) -> Vacuum Cleaner | Q4: =_xlfn.XLOOKUP(tbl_sale[[#This Row],[Product ID]],ProductMaster!$A$2:$A$23,ProductMaster!$C$2:$C$23,"NA",0) -> Home | R4: =IFERROR(IF(tbl_sale[[#This Row],[Delivery Date]]="","Pending",IF(tbl_sale[[#This Row],[Delivery Date]]-tbl_sale[[#This Row],[Order Date]]<= 2,"Fast","Slow")),"Error") -> Pending | S4: =_xlfn.XLOOKUP(tbl_sale[[#This Row],[Region]],RegionGoals!$A$2:$A$6,RegionGoals!$B$2:$B$6, ,0) -> 91500 | T4: =_xlfn.XLOOKUP(tbl_sale[[#This Row],[Customer ID]],CustomerMaster!$A:$A,CustomerMaster!$C:$C,"NA",0) -> Individual | U4: =IF(tbl_sale[[#This Row],[Delivery Status]]="Cancelled",1,0) -> 0 | V4: =IF(tbl_sale[[#This Row],[Order ID]]<>"",1,0) -> 1 | W4: =IF(AND(tbl_sale[[#This Row],[Delivery Status]]="Delivered",tbl_sale[[#This Row],[Delivery Performance]]="Fast"),1,0) -> 0 | X4: =IF(tbl_sale[[#This Row],[Delivery Status]]="Delivered",1,0) -> 0
A5: ORD0004 | B5: 45051 | D5: 45057 | E5: =TEXT(tbl_sale[[#This Row],[Order Date]],"MMM") -> May | F5: =IF(D5<>"","Cancelled",IF(C5<>"","Delivered","In Transit")) -> Cancelled | G5: CUST044 | H5: PROD013 | I5: North | J5: 196 | K5: 3 | L5: 588 | M5: PayPal | N5: UPS | O5: =_xlfn.XLOOKUP(tbl_sale[[#This Row],[Customer ID]],CustomerMaster!A:A,CustomerMaster!B:B,"NA",0) -> Grace Ward | P5: =_xlfn.XLOOKUP(tbl_sale[[#This Row],[Product ID]],ProductMaster!$A$2:$A$23,ProductMaster!$B$2:$B$23,"NA",0) -> Vacuum Cleaner | Q5: =_xlfn.XLOOKUP(tbl_sale[[#This Row],[Product ID]],ProductMaster!$A$2:$A$23,ProductMaster!$C$2:$C$23,"NA",0) -> Home | R5: =IFERROR(IF(tbl_sale[[#This Row],[Delivery Date]]="","Pending",IF(tbl_sale[[#This Row],[Delivery Date]]-tbl_sale[[#This Row],[Order Date]]<= 2,"Fast","Slow")),"Error") -> Pending | S5: =_xlfn.XLOOKUP(tbl_sale[[#This Row],[Region]],RegionGoals!$A$2:$A$6,RegionGoals!$B$2:$B$6, ,0) -> 105000 | T5: =_xlfn.XLOOKUP(tbl_sale[[#This Row],[Customer ID]],CustomerMaster!$A:$A,CustomerMaster!$C:$C,"NA",0) -> Business | U5: =IF(tbl_sale[[#This Row],[Delivery Status]]="Cancelled",1,0) -> 1 | V5: =IF(tbl_sale[[#This Row],[Order ID]]<>"",1,0) -> 1 | W5: =IF(AND(tbl_sale[[#This Row],[Delivery Status]]="Delivered",tbl_sale[[#This Row],[Delivery Performance]]="Fast"),1,0) -> 0 | X5: =IF(tbl_sale[[#This Row],[Delivery Status]]="Delivered",1,0) -> 0
A6: ORD0005 | B6: 44959 | C6: 44962 | E6: =TEXT(tbl_sale[[#This Row],[Order Date]],"MMM") -> Feb | F6: =IF(D6<>"","Cancelled",IF(C6<>"","Delivered","In Transit")) -> Delivered | G6: CUST027 | H6: PROD010 | I6: North | J6: 59 | K6: 1 | L6: 59 | M6: PayPal | N6: Amazon Logistics | O6: =_xlfn.XLOOKUP(tbl_sale[[#This Row],[Customer ID]],CustomerMaster!A:A,CustomerMaster!B:B,"NA",0) -> Hazel Brooks | P6: =_xlfn.XLOOKUP(tbl_sale[[#This Row],[Product ID]],ProductMaster!$A$2:$A$23,ProductMaster!$B$2:$B$23,"NA",0) -> Jeans | Q6: =_xlfn.XLOOKUP(tbl_sale[[#This Row],[Product ID]],ProductMaster!$A$2:$A$23,ProductMaster!$C$2:$C$23,"NA",0) -> Fashion | R6: =IFERROR(IF(tbl_sale[[#This Row],[Delivery Date]]="","Pending",IF(tbl_sale[[#This Row],[Delivery Date]]-tbl_sale[[#This Row],[Order Date]]<= 2,"Fast","Slow")),"Error") -> Slow | S6: =_xlfn.XLOOKUP(tbl_sale[[#This Row],[Region]],RegionGoals!$A$2:$A$6,RegionGoals!$B$2:$B$6, ,0) -> 105000 | T6: =_xlfn.XLOOKUP(tbl_sale[[#This Row],[Customer ID]],CustomerMaster!$A:$A,CustomerMaster!$C:$C,"NA",0) -> Individual | U6: =IF(tbl_sale[[#This Row],[Delivery Status]]="Cancelled",1,0) -> 0 | V6: =IF(tbl_sale[[#This Row],[Order ID]]<>"",1,0) -> 1 | W6: =IF(AND(tbl_sale[[#This Row],[Delivery Status]]="Delivered",tbl_sale[[#This Row],[Delivery Performance]]="Fast"),1,0) -> 0 | X6: =IF(tbl_sale[[#This Row],[Delivery Status]]="Delivered",1,0) -> 1
A7: ORD0006 | B7: 45231 | D7: 45232 | E7: =TEXT(tbl_sale[[#This Row],[Order Date]],"MMM") -> Nov | F7: =IF(D7<>"","Cancelled",IF(C7<>"","Delivered","In Transit")) -> Cancelled | G7: CUST009 | H7: PROD010 | I7: North | J7: 58 | K7: 4 | L7: 232 | M7: Amazon Pay | N7: DHL | O7: =_xlfn.XLOOKUP(tbl_sale[[#This Row],[Customer ID]],CustomerMaster!A:A,CustomerMaster!B:B,"NA",0) -> Jackson Allen | P7: =_xlfn.XLOOKUP(tbl_sale[[#This Row],[Product ID]],ProductMaster!$A$2:$A$23,ProductMaster!$B$2:$B$23,"NA",0) -> Jeans | Q7: =_xlfn.XLOOKUP(tbl_sale[[#This Row],[Product ID]],ProductMaster!$A$2:$A$23,ProductMaster!$C$2:$C$23,"NA",0) -> Fashion | R7: =IFERROR(IF(tbl_sale[[#This Row],[Delivery Date]]="","Pending",IF(tbl_sale[[#This Row],[Delivery Date]]-tbl_sale[[#This Row],[Order Date]]<= 2,"Fast","Slow")),"Error") -> Pending | S7: =_xlfn.XLOOKUP(tbl_sale[[#This Row],[Region]],RegionGoals!$A$2:$A$6,RegionGoals!$B$2:$B$6, ,0) -> 105000 | T7: =_xlfn.XLOOKUP(tbl_sale[[#This Row],[Customer ID]],CustomerMaster!$A:$A,CustomerMaster!$C:$C,"NA",0) -> Business | U7: =IF(tbl_sale[[#This Row],[Delivery Status]]="Cancelled",1,0) -> 1 | V7: =IF(tbl_sale[[#This Row],[Order ID]]<>"",1,0) -> 1 | W7: =IF(AND(tbl_sale[[#This Row],[Delivery Status]]="Delivered",tbl_sale[[#This Row],[Delivery Performance]]="Fast"),1,0) -> 0 | X7: =IF(tbl_sale[[#This Row],[Delivery Status]]="Delivered",1,0) -> 0
A8: ORD0007 | B8: 45152 | D8: 45156 | E8: =TEXT(tbl_sale[[#This Row],[Order Date]],"MMM") -> Aug | F8: =IF(D8<>"","Cancelled",IF(C8<>"","Delivered","In Transit")) -> Cancelled | G8: CUST042 | H8: PROD020 | I8: Central | J8: 105 | K8: 3 | L8: 315 | M8: Debit Card | N8: DHL | O8: =_xlfn.XLOOKUP(tbl_sale[[#This Row],[Customer ID]],CustomerMaster!A:A,CustomerMaster!B:B,"NA",0) -> Noah Wilson | P8: =_xlfn.XLOOKUP(tbl_sale[[#This Row],[Product ID]],ProductMaster!$A$2:$A$23,ProductMaster!$B$2:$B$23,"NA",0) -> Bluetooth Speaker | Q8: =_xlfn.XLOOKUP(tbl_sale[[#This Row],[Product ID]],ProductMaster!$A$2:$A$23,ProductMaster!$C$2:$C$23,"NA",0) -> Electronics | R8: =IFERROR(IF(tbl_sale[[#This Row],[Delivery Date]]="","Pending",IF(tbl_sale[[#This Row],[Delivery Date]]-tbl_sale[[#This Row],[Order Date]]<= 2,"Fast","Slow")),"Error") -> Pending | S8: =_xlfn.XLOOKUP(tbl_sale[[#This Row],[Region]],RegionGoals!$A$2:$A$6,RegionGoals!$B$2:$B$6, ,0) -> 97500 | T8: =_xlfn.XLOOKUP(tbl_sale[[#This Row],[Customer ID]],CustomerMaster!$A:$A,CustomerMaster!$C:$C,"NA",0) -> Prime | U8: =IF(tbl_sale[[#This Row],[Delivery Status]]="Cancelled",1,0) -> 1 | V8: =IF(tbl_sale[[#This Row],[Order ID]]<>"",1,0) -> 1 | W8: =IF(AND(tbl_sale[[#This Row],[Delivery Status]]="Delivered",tbl_sale[[#This Row],[Delivery Performance]]="Fast"),1,0) -> 0 | X8: =IF(tbl_sale[[#This Row],[Delivery Status]]="Delivered",1,0) -> 0
A9: ORD0008 | B9: 45017 | D9: 45022 | E9: =TEXT(tbl_sale[[#This Row],[Order Date]],"MMM") -> Apr | F9: =IF(D9<>"","Cancelled",IF(C9<>"","Delivered","In Transit")) -> Cancelled | G9: CUST019 | H9: PROD021 | I9: West | J9: 37 | K9: 5 | L9: 185 | M9: PayPal | N9: DHL | O9: =_xlfn.XLOOKUP(tbl_sale[[#This Row],[Customer ID]],CustomerMaster!A:A,CustomerMaster!B:B,"NA",0) -> Ava Robinson | P9: =_xlfn.XLOOKUP(tbl_sale[[#This Row],[Product ID]],ProductMaster!$A$2:$A$23,ProductMaster!$B$2:$B$23,"NA",0) -> Wall Clock | Q9: =_xlfn.XLOOKUP(tbl_sale[[#This Row],[Product ID]],ProductMaster!$A$2:$A$23,ProductMaster!$C$2:$C$23,"NA",0) -> Home | R9: =IFERROR(IF(tbl_sale[[#This Row],[Delivery Date]]="","Pending",IF(tbl_sale[[#This Row],[Delivery Date]]-tbl_sale[[#This Row],[Order Date]]<= 2,"Fast","Slow")),"Error") -> Pending | S9: =_xlfn.XLOOKUP(tbl_sale[[#This Row],[Region]],RegionGoals!$A$2:$A$6,RegionGoals!$B$2:$B$6, ,0) -> 90750 | T9: =_xlfn.XLOOKUP(tbl_sale[[#This Row],[Customer ID]],CustomerMaster!$A:$A,CustomerMaster!$C:$C,"NA",0) -> Prime | U9: =IF(tbl_sale[[#This Row],[Delivery Status]]="Cancelled",1,0) -> 1 | V9: =IF(tbl_sale[[#This Row],[Order ID]]<>"",1,0) -> 1 | W9: =IF(AND(tbl_sale[[#This Row],[Delivery Status]]="Delivered",tbl_sale[[#This Row],[Delivery Performance]]="Fast"),1,0) -> 0 | X9: =IF(tbl_sale[[#This Row],[Delivery Status]]="Delivered",1,0) -> 0
A10: ORD0009 | B10: 45128 | E10: =TEXT(tbl_sale[[#This Row],[Order Date]],"MMM") -> Jul | F10: =IF(D10<>"","Cancelled",IF(C10<>"","Delivered","In Transit")) -> In Transit | G10: CUST013 | H10: PROD019 | I10: Central | J10: 44 | K10: 2 | L10: 88 | M10: Credit Card | N10: Amazon Logistics | O10: =_xlfn.XLOOKUP(tbl_sale[[#This Row],[Customer ID]],CustomerMaster!A:A,CustomerMaster!B:B,"NA",0) -> Olivia Martinez | P10: =_xlfn.XLOOKUP(tbl_sale[[#This Row],[Product ID]],ProductMaster!$A$2:$A$23,ProductMaster!$B$2:$B$23,"NA",0) -> Formal Shirt | Q10: =_xlfn.XLOOKUP(tbl_sale[[#This Row],[Product ID]],ProductMaster!$A$2:$A$23,ProductMaster!$C$2:$C$23,"NA",0) -> Fashion | R10: =IFERROR(IF(tbl_sale[[#This Row],[Delivery Date]]="","Pending",IF(tbl_sale[[#This Row],[Delivery Date]]-tbl_sale[[#This Row],[Order Date]]<= 2,"Fast","Slow")),"Error") -> Pending | S10: =_xlfn.XLOOKUP(tbl_sale[[#This Row],[Region]],RegionGoals!$A$2:$A$6,RegionGoals!$B$2:$B$6, ,0) -> 97500 | T10: =_xlfn.XLOOKUP(tbl_sale[[#This Row],[Customer ID]],CustomerMaster!$A:$A,CustomerMaster!$C:$C,"NA",0) -> Prime | U10: =IF(tbl_sale[[#This Row],[Delivery Status]]="Cancelled",1,0) -> 0 | V10: =IF(tbl_sale[[#This Row],[Order ID]]<>"",1,0) -> 1 | W10: =IF(AND(tbl_sale[[#This Row],[Delivery Status]]="Delivered",tbl_sale[[#This Row],[Delivery Performance]]="Fast"),1,0) -> 0 | X10: =IF(tbl_sale[[#This Row],[Delivery Status]]="Delivered",1,0) -> 0
A11: ORD0010 | B11: 45289 | E11: =TEXT(tbl_sale[[#This Row],[Order Date]],"MMM") -> Dec | F11: =IF(D11<>"","Cancelled",IF(C11<>"","Delivered","In Transit")) -> In Transit | G11: CUST019 | H11: PROD003 | I11: South | J11: 141 | K11: 4 | L11: 564 | M11: Debit Card | N11: DHL | O11: =_xlfn.XLOOKUP(tbl_sale[[#This Row],[Customer ID]],CustomerMaster!A:A,CustomerMaster!B:B,"NA",0) -> Ava Robinson | P11: =_xlfn.XLOOKUP(tbl_sale[[#This Row],[Product ID]],ProductMaster!$A$2:$A$23,ProductMaster!$B$2:$B$23,"NA",0) -> Cookware Set | Q11: =_xlfn.XLOOKUP(tbl_sale[[#This Row],[Product ID]],ProductMaster!$A$2:$A$23,ProductMaster!$C$2:$C$23,"NA",0) -> Home | R11: =IFERROR(IF(tbl_sale[[#This Row],[Delivery Date]]="","Pending",IF(tbl_sale[[#This Row],[Delivery Date]]-tbl_sale[[#This Row],[Order Date]]<= 2,"Fast","Slow")),"Error") -> Pending | S11: =_xlfn.XLOOKUP(tbl_sale[[#This Row],[Region]],RegionGoals!$A$2:$A$6,RegionGoals!$B$2:$B$6, ,0) -> 91500 | T11: =_xlfn.XLOOKUP(tbl_sale[[#This Row],[Customer ID]],CustomerMaster!$A:$A,CustomerMaster!$C:$C,"NA",0) -> Prime | U11: =IF(tbl_sale[[#This Row],[Delivery Status]]="Cancelled",1,0) -> 0 | V11: =IF(tbl_sale[[#This Row],[Order ID]]<>"",1,0) -> 1 | W11: =IF(AND(tbl_sale[[#This Row],[Delivery Status]]="Delivered",tbl_sale[[#This Row],[Delivery Performance]]="Fast"),1,0) -> 0 | X11: =IF(tbl_sale[[#This Row],[Delivery Status]]="Delivered",1,0) -> 0
A12: ORD0011 | B12: 45050 | D12: 45054 | E12: =TEXT(tbl_sale[[#This Row],[Order Date]],"MMM") -> May | F12: =IF(D12<>"","Cancelled",IF(C12<>"","Delivered","In Transit")) -> Cancelled | G12: CUST046 | H12: PROD014 | I12: South | J12: 249 | K12: 1 | L12: 249 | M12: Amazon Pay | N12: USPS | O12: =_xlfn.XLOOKUP(tbl_sale[[#This Row],[Customer ID]],CustomerMaster!A:A,CustomerMaster!B:B,"NA",0) -> Emily Johnson | P12: =_xlfn.XLOOKUP(tbl_sale[[#This Row],[Product ID]],ProductMaster!$A$2:$A$23,ProductMaster!$B$2:$B$23,"NA",0) -> Smartwatch | Q12: =_xlfn.XLOOKUP(tbl_sale[[#This Row],[Product ID]],ProductMaster!$A$2:$A$23,ProductMaster!$C$2:$C$23,"NA",0) -> Electronics | R12: =IFERROR(IF(tbl_sale[[#This Row],[Delivery Date]]="","Pending",IF(tbl_sale[[#This Row],[Delivery Date]]-tbl_sale[[#This Row],[Order Date]]<= 2,"Fast","Slow")),"Error") -> Pending | S12: =_xlfn.XLOOKUP(tbl_sale[[#This Row],[Region]],RegionGoals!$A$2:$A$6,RegionGoals!$B$2:$B$6, ,0) -> 91500 | T12: =_xlfn.XLOOKUP(tbl_sale[[#This Row],[Customer ID]],CustomerMaster!$A:$A,CustomerMaster!$C:$C,"NA",0) -> Prime | U12: =IF(tbl_sale[[#This Row],[Delivery Status]]="Cancelled",1,0) -> 1 | V12: =IF(tbl_sale[[#This Row],[Order ID]]<>"",1,0) -> 1 | W12: =IF(AND(tbl_sale[[#This Row],[Delivery Status]]="Delivered",tbl_sale[[#This Row],[Delivery Performance]]="Fast"),1,0) -> 0 | X12: =IF(tbl_sale[[#This Row],[Delivery Status]]="Delivered",1,0) -> 0
A13: ORD0012 | B13: 45132 | E13: =TEXT(tbl_sale[[#This Row],[Order Date]],"MMM") -> Jul | F13: =IF(D13<>"","Cancelled",IF(C13<>"","Delivered","In Transit")) -> In Transit | G13: CUST045 | H13: PROD014 | I13: Central | J13: 247 | K13: 3 | L13: 741 | M13: Amazon Pay | N13: FedEx | O13: =_xlfn.XLOOKUP(tbl_sale[[#This Row],[Customer ID]],CustomerMaster!A:A,CustomerMaster!B:B,"NA",0) -> Emily Johnson | P13: =_xlfn.XLOOKUP(tbl_sale[[#This Row],[Product ID]],ProductMaster!$A$2:$A$23,ProductMaster!$B$2:$B$23,"NA",0) -> Smartwatch | Q13: =_xlfn.XLOOKUP(tbl_sale[[#This Row],[Product ID]],ProductMaster!$A$2:$A$23,ProductMaster!$C$2:$C$23,"NA",0) -> Electronics | R13: =IFERROR(IF(tbl_sale[[#This Row],[Delivery Date]]="","Pending",IF(tbl_sale[[#This Row],[Delivery Date]]-tbl_sale[[#This Row],[Order Date]]<= 2,"Fast","Slow")),"Error") -> Pending | S13: =_xlfn.XLOOKUP(tbl_sale[[#This Row],[Region]],RegionGoals!$A$2:$A$6,RegionGoals!$B$2:$B$6, ,0) -> 97500 | T13: =_xlfn.XLOOKUP(tbl_sale[[#This Row],[Customer ID]],CustomerMaster!$A:$A,CustomerMaster!$C:$C,"NA",0) -> Individual | U13: =IF(tbl_sale[[#This Row],[Delivery Status]]="Cancelled",1,0) -> 0 | V13: =IF(tbl_sale[[#This Row],[Order ID]]<>"",1,0) -> 1 | W13: =IF(AND(tbl_sale[[#This Row],[Delivery Status]]="Delivered",tbl_sale[[#This Row],[Delivery Performance]]="Fast"),1,0) -> 0 | X13: =IF(tbl_sale[[#This Row],[Delivery Status]]="Delivered",1,0) -> 0
A14: ORD0013 | B14: 44982 | D14: 44985 | E14: =TEXT(tbl_sale[[#This Row],[Order Date]],"MMM") -> Feb | F14: =IF(D14<>"","Cancelled",IF(C14<>"","Delivered","In Transit")) -> Cancelled | G14: CUST023 | H14: PROD006 | I14: Central | J14: 96 | K14: 1 | L14: 96 | M14: Apple Pay | N14: Amazon Logistics | O14: =_xlfn.XLOOKUP(tbl_sale[[#This Row],[Customer ID]],CustomerMaster!A:A,CustomerMaster!B:B,"NA",0) -> Charlotte Reed | P14: =_xlfn.XLOOKUP(tbl_sale[[#This Row],[Product ID]],ProductMaster!$A$2:$A$23,ProductMaster!$B$2:$B$23,"NA",0) -> Shoes | Q14: =_xlfn.XLOOKUP(tbl_sale[[#This Row],[Product ID]],ProductMaster!$A$2:$A$23,ProductMaster!$C$2:$C$23,"NA",0) -> Fashion | R14: =IFERROR(IF(tbl_sale[[#This Row],[Delivery Date]]="","Pending",IF(tbl_sale[[#This Row],[Delivery Date]]-tbl_sale[[#This Row],[Order Date]]<= 2,"Fast","Slow")),"Error") -> Pending | S14: =_xlfn.XLOOKUP(tbl_sale[[#This Row],[Region]],RegionGoals!$A$2:$A$6,RegionGoals!$B$2:$B$6, ,0) -> 97500 | T14: =_xlfn.XLOOKUP(tbl_sale[[#This Row],[Customer ID]],CustomerMaster!$A:$A,CustomerMaster!$C:$C,"NA",0) -> Individual | U14: =IF(tbl_sale[[#This Row],[Delivery Status]]="Cancelled",1,0) -> 1 | V14: =IF(tbl_sale[[#This Row],[Order ID]]<>"",1,0) -> 1 | W14: =IF(AND(tbl_sale[[#This Row],[Delivery Status]]="Delivered",tbl_sale[[#This Row],[Delivery Performance]]="Fast"),1,0) -> 0 | X14: =IF(tbl_sale[[#This Row],[Delivery Status]]="Delivered",1,0) -> 0
A15: ORD0014 | B15: 44981 | D15: 44982 | E15: =TEXT(tbl_sale[[#This Row],[Order Date]],"MMM") -> Feb | F15: =IF(D15<>"","Cancelled",IF(C15<>"","Delivered","In Transit")) -> Cancelled | G15: CUST033 | H15: PROD017 | I15: West | J15: 74 | K15: 5 | L15: 370 | M15: Apple Pay | N15: Amazon Logistics | O15: =_xlfn.XLOOKUP(tbl_sale[[#This Row],[Customer ID]],CustomerMaster!A:A,CustomerMaster!B:B,"NA",0) -> Hazel Rivera | P15: =_xlfn.XLOOKUP(tbl_sale[[#This Row],[Product ID]],ProductMaster!$A$2:$A$23,ProductMaster!$B$2:$B$23,"NA",0) -> Gaming Mouse | Q15: =_xlfn.XLOOKUP(tbl_sale[[#This Row],[Product ID]],ProductMaster!$A$2:$A$23,ProductMaster!$C$2:$C$23,"NA",0) -> Electronics | R15: =IFERROR(IF(tbl_sale[[#This Row],[Delivery Date]]="","Pending",IF(tbl_sale[[#This Row],[Delivery Date]]-tbl_sale[[#This Row],[Order Date]]<= 2,"Fast","Slow")),"Error") -> Pending | S15: =_xlfn.XLOOKUP(tbl_sale[[#This Row],[Region]],RegionGoals!$A$2:$A$6,RegionGoals!$B$2:$B$6, ,0) -> 90750 | T15: =_xlfn.XLOOKUP(tbl_sale[[#This Row],[Customer ID]],CustomerMaster!$A:$A,CustomerMaster!$C:$C,"NA",0) -> Business | U15: =IF(tbl_sale[[#This Row],[Delivery Status]]="Cancelled",1,0) -> 1 | V15: =IF(tbl_sale[[#This Row],[Order ID]]<>"",1,0) -> 1 | W15: =IF(AND(tbl_sale[[#This Row],[Delivery Status]]="Delivered",tbl_sale[[#This Row],[Delivery Performance]]="Fast"),1,0) -> 0 | X15: =IF(tbl_sale[[#This Row],[Delivery Status]]="Delivered",1,0) -> 0
A16: ORD0015 | B16: 45164 | D16: 45171 | E16: =TEXT(tbl_sale[[#This Row],[Order Date]],"MMM") -> Aug | F16: =IF(D16<>"","Cancelled",IF(C16<>"","Delivered","In Transit")) -> Cancelled | G16: CUST033 | H16: PROD005 | I16: South | J16: 27 | K16: 1 | L16: 27 | M16: Credit Card | N16: Amazon Logistics | O16: =_xlfn.XLOOKUP(tbl_sale[[#This Row],[Customer ID]],CustomerMaster!A:A,CustomerMaster!B:B,"NA",0) -> Hazel Rivera | P16: =_xlfn.XLOOKUP(tbl_sale[[#This Row],[Product ID]],ProductMaster!$A$2:$A$23,ProductMaster!$B$2:$B$23,"NA",0) -> T-Shirt | Q16: =_xlfn.XLOOKUP(tbl_sale[[#This Row],[Product ID]],ProductMaster!$A$2:$A$23,ProductMaster!$C$2:$C$23,"NA",0) -> Fashion | R16: =IFERROR(IF(tbl_sale[[#This Row],[Delivery Date]]="","Pending",IF(tbl_sale[[#This Row],[Delivery Date]]-tbl_sale[[#This Row],[Order Date]]<= 2,"Fast","Slow")),"Error") -> Pending | S16: =_xlfn.XLOOKUP(tbl_sale[[#This Row],[Region]],RegionGoals!$A$2:$A$6,RegionGoals!$B$2:$B$6, ,0) -> 91500 | T16: =_xlfn.XLOOKUP(tbl_sale[[#This Row],[Customer ID]],CustomerMaster!$A:$A,CustomerMaster!$C:$C,"NA",0) -> Business | U16: =IF(tbl_sale[[#This Row],[Delivery Status]]="Cancelled",1,0) -> 1 | V16: =IF(tbl_sale[[#This Row],[Order ID]]<>"",1,0) -> 1 | W16: =IF(AND(tbl_sale[[#This Row],[Delivery Status]]="Delivered",tbl_sale[[#This Row],[Delivery Performance]]="Fast"),1,0) -> 0 | X16: =IF(tbl_sale[[#This Row],[Delivery Status]]="Delivered",1,0) -> 0
A17: ORD0016 | B17: 44970 | E17: =TEXT(tbl_sale[[#This Row],[Order Date]],"MMM") -> Feb | F17: =IF(D17<>"","Cancelled",IF(C17<>"","Delivered","In Transit")) -> In Transit | G17: CUST047 | H17: PROD005 | I17: South | J17: 27 | K17: 3 | L17: 81 | M17: Debit Card | N17: Amazon Logistics | O17: =_xlfn.XLOOKUP(tbl_sale[[#This Row],[Customer ID]],CustomerMaster!A:A,CustomerMaster!B:B,"NA",0) -> Scarlett Murphy | P17: =_xlfn.XLOOKUP(tbl_sale[[#This Row],[Product ID]],ProductMaster!$A$2:$A$23,ProductMaster!$B$2:$B$23,"NA",0) -> T-Shirt | Q17: =_xlfn.XLOOKUP(tbl_sale[[#This Row],[Product ID]],ProductMaster!$A$2:$A$23,ProductMaster!$C$2:$C$23,"NA",0) -> Fashion | R17: =IFERROR(IF(tbl_sale[[#This Row],[Delivery Date]]="","Pending",IF(tbl_sale[[#This Row],[Delivery Date]]-tbl_sale[[#This Row],[Order Date]]<= 2,"Fast","Slow")),"Error") -> Pending | S17: =_xlfn.XLOOKUP(tbl_sale[[#This Row],[Region]],RegionGoals!$A$2:$A$6,RegionGoals!$B$2:$B$6, ,0) -> 91500 | T17: =_xlfn.XLOOKUP(tbl_sale[[#This Row],[Customer ID]],CustomerMaster!$A:$A,CustomerMaster!$C:$C,"NA",0) -> Individual | U17: =IF(tbl_sale[[#This Row],[Delivery Status]]="Cancelled",1,0) -> 0 | V17: =IF(tbl_sale[[#This Row],[Order ID]]<>"",1,0) -> 1 | W17: =IF(AND(tbl_sale[[#This Row],[Delivery Status]]="Delivered",tbl_sale[[#This Row],[Delivery Performance]]="Fast"),1,0) -> 0 | X17: =IF(tbl_sale[[#This Row],[Delivery Status]]="Delivered",1,0) -> 0
A18: ORD0017 | B18: 45105 | C18: 45108 | E18: =TEXT(tbl_sale[[#This Row],[Order Date]],"MMM") -> Jun | F18: =IF(D18<>"","Cancelled",IF(C18<>"","Delivered","In Transit")) -> Delivered | G18: CUST045 | H18: PROD015 | I18: East | J18: 21 | K18: 3 | L18: 63 | M18: Credit Card | N18: DHL | O18: =_xlfn.XLOOKUP(tbl_sale[[#This Row],[Customer ID]],CustomerMaster!A:A,CustomerMaster!B:B,"NA",0) -> Emily Johnson | P18: =_xlfn.XLOOKUP(tbl_sale[[#This Row],[Product ID]],ProductMaster!$A$2:$A$23,ProductMaster!$B$2:$B$23,"NA",0) -> Novel | Q18: =_xlfn.XLOOKUP(tbl_sale[[#This Row],[Product ID]],ProductMaster!$A$2:$A$23,ProductMaster!$C$2:$C$23,"NA",0) -> Books | R18: =IFERROR(IF(tbl_sale[[#This Row],[Delivery Date]]="","Pending",IF(tbl_sale[[#This Row],[Delivery Date]]-tbl_sale[[#This Row],[Order Date]]<= 2,"Fast","Slow")),"Error") -> Slow | S18: =_xlfn.XLOOKUP(tbl_sale[[#This Row],[Region]],RegionGoals!$A$2:$A$6,RegionGoals!$B$2:$B$6, ,0) -> 50500 | T18: =_xlfn.XLOOKUP(tbl_sale[[#This Row],[Customer ID]],CustomerMaster!$A:$A,CustomerMaster!$C:$C,"NA",0) -> Individual | U18: =IF(tbl_sale[[#This Row],[Delivery Status]]="Cancelled",1,0) -> 0 | V18: =IF(tbl_sale[[#This Row],[Order ID]]<>"",1,0) -> 1 | W18: =IF(AND(tbl_sale[[#This Row],[Delivery Status]]="Delivered",tbl_sale[[#This Row],[Delivery Performance]]="Fast"),1,0) -> 0 | X18: =IF(tbl_sale[[#This Row],[Delivery Status]]="Delivered",1,0) -> 1
A19: ORD0018 | B19: 45258 | E19: =TEXT(tbl_sale[[#This Row],[Order Date]],"MMM") -> Nov | F19: =IF(D19<>"","Cancelled",IF(C19<>"","Delivered","In Transit")) -> In Transit | G19: CUST011 | H19: PROD008 | I19: West | J19: 70 | K19: 5 | L19: 350 | M19: PayPal | N19: Amazon Logistics | O19: =_xlfn.XLOOKUP(tbl_sale[[#This Row],[Customer ID]],CustomerMaster!A:A,CustomerMaster!B:B,"NA",0) -> Mason Hall | P19: =_xlfn.XLOOKUP(tbl_sale[[#This Row],[Product ID]],ProductMaster!$A$2:$A$23,ProductMaster!$B$2:$B$23,"NA",0) -> Textbook | Q19: =_xlfn.XLOOKUP(tbl_sale[[#This Row],[Product ID]],ProductMaster!$A$2:$A$23,ProductMaster!$C$2:$C$23,"NA",0) -> Books | R19: =IFERROR(IF(tbl_sale[[#This Row],[Delivery Date]]="","Pending",IF(tbl_sale[[#This Row],[Delivery Date]]-tbl_sale[[#This Row],[Order Date]]<= 2,"Fast","Slow")),"Error") -> Pending | S19: =_xlfn.XLOOKUP(tbl_sale[[#This Row],[Region]],RegionGoals!$A$2:$A$6,RegionGoals!$B$2:$B$6, ,0) -> 90750 | T19: =_xlfn.XLOOKUP(tbl_sale[[#This Row],[Customer ID]],CustomerMaster!$A:$A,CustomerMaster!$C:$C,"NA",0) -> Business | U19: =IF(tbl_sale[[#This Row],[Delivery Status]]="Cancelled",1,0) -> 0 | V19: =IF(tbl_sale[[#This Row],[Order ID]]<>"",1,0) -> 1 | W19: =IF(AND(tbl_sale[[#This Row],[Delivery Status]]="Delivered",tbl_sale[[#This Row],[Delivery Performance]]="Fast"),1,0) -> 0 | X19: =IF(tbl_sale[[#This Row],[Delivery Status]]="Delivered",1,0) -> 0
A20: ORD0019 | B20: 45163 | E20: =TEXT(tbl_sale[[#This Row],[Order Date]],"MMM") -> Aug | F20: =IF(D20<>"","Cancelled",IF(C20<>"","Delivered","In Transit")) -> In Transit | G20: CUST041 | H20: PROD006 | I20: South | J20: 94 | K20: 4 | L20: 376 | M20: Credit Card | N20: USPS | O20: =_xlfn.XLOOKUP(tbl_sale[[#This Row],[Customer ID]],CustomerMaster!A:A,CustomerMaster!B:B,"NA",0) -> Jacob Price | P20: =_xlfn.XLOOKUP(tbl_sale[[#This Row],[Product ID]],ProductMaster!$A$2:$A$23,ProductMaster!$B$2:$B$23,"NA",0) -> Shoes | Q20: =_xlfn.XLOOKUP(tbl_sale[[#This Row],[Product ID]],ProductMaster!$A$2:$A$23,ProductMaster!$C$2:$C$23,"NA",0) -> Fashion | R20: =IFERROR(IF(tbl_sale[[#This Row],[Delivery Date]]="","Pending",IF(tbl_sale[[#This Row],[Delivery Date]]-tbl_sale[[#This Row],[Order Date]]<= 2,"Fast","Slow")),"Error") -> Pending | S20: =_xlfn.XLOOKUP(tbl_sale[[#This Row],[Region]],RegionGoals!$A$2:$A$6,RegionGoals!$B$2:$B$6, ,0) -> 91500 | T20: =_xlfn.XLOOKUP(tbl_sale[[#This Row],[Customer ID]],CustomerMaster!$A:$A,CustomerMaster!$C:$C,"NA",0) -> Business | U20: =IF(tbl_sale[[#This Row],[Delivery Status]]="Cancelled",1,0) -> 0 | V20: =IF(tbl_sale[[#This Row],[Order ID]]<>"",1,0) -> 1 | W20: =IF(AND(tbl_sale[[#This Row],[Delivery Status]]="Delivered",tbl_sale[[#This Row],[Delivery Performance]]="Fast"),1,0) -> 0 | X20: =IF(tbl_sale[[#This Row],[Delivery Status]]="Delivered",1,0) -> 0
A21: ORD0020 | B21: 45028 | E21: =TEXT(tbl_sale[[#This Row],[Order Date]],"MMM") -> Apr | F21: =IF(D21<>"","Cancelled",IF(C21<>"","Delivered","In Transit")) -> In Transit | G21: CUST025 | H21: PROD001 | I21: North | J21: 813 | K21: 2 | L21: 1626 | M21: Credit Card | N21: FedEx | O21: =_xlfn.XLOOKUP(tbl_sale[[#This Row],[Customer ID]],CustomerMaster!A:A,CustomerMaster!B:B,"NA",0) -> Emma King | P21: =_xlfn.XLOOKUP(tbl_sale[[#This Row],[Product ID]],ProductMaster!$A$2:$A$23,ProductMaster!$B$2:$B$23,"NA",0) -> Smartphone | Q21: =_xlfn.XLOOKUP(tbl_sale[[#This Row],[Product ID]],ProductMaster!$A$2:$A$23,ProductMaster!$C$2:$C$23,"NA",0) -> Electronics | R21: =IFERROR(IF(tbl_sale[[#This Row],[Delivery Date]]="","Pending",IF(tbl_sale[[#This Row],[Delivery Date]]-tbl_sale[[#This Row],[Order Date]]<= 2,"Fast","Slow")),"Error") -> Pending | S21: =_xlfn.XLOOKUP(tbl_sale[[#This Row],[Region]],RegionGoals!$A$2:$A$6,RegionGoals!$B$2:$B$6, ,0) -> 105000 | T21: =_xlfn.XLOOKUP(tbl_sale[[#This Row],[Customer ID]],CustomerMaster!$A:$A,CustomerMaster!$C:$C,"NA",0) -> Individual | U21: =IF(tbl_sale[[#This Row],[Delivery Status]]="Cancelled",1,0) -> 0 | V21: =IF(tbl_sale[[#This Row],[Order ID]]<>"",1,0) -> 1 | W21: =IF(AND(tbl_sale[[#This Row],[Delivery Status]]="Delivered",tbl_sale[[#This Row],[Delivery Performance]]="Fast"),1,0) -> 0 | X21: =IF(tbl_sale[[#This Row],[Delivery Status]]="Delivered",1,0) -> 0
A22: ORD0021 | B22: 45201 | E22: =TEXT(tbl_sale[[#This Row],[Order Date]],"MMM") -> Oct | F22: =IF(D22<>"","Cancelled",IF(C22<>"","Delivered","In Transit")) -> In Transit | G22: CUST013 | H22: PROD015 | I22: Central | J22: 21 | K22: 4 | L22: 84 | M22: PayPal | N22: Amazon Logistics | O22: =_xlfn.XLOOKUP(tbl_sale[[#This Row],[Customer ID]],CustomerMaster!A:A,CustomerMaster!B:B,"NA",0) -> Olivia Martinez | P22: =_xlfn.XLOOKUP(tbl_sale[[#This Row],[Product ID]],ProductMaster!$A$2:$A$23,ProductMaster!$B$2:$B$23,"NA",0) -> Novel | Q22: =_xlfn.XLOOKUP(tbl_sale[[#This Row],[Product ID]],ProductMaster!$A$2:$A$23,ProductMaster!$C$2:$C$23,"NA",0) -> Books | R22: =IFERROR(IF(tbl_sale[[#This Row],[Delivery Date]]="","Pending",IF(tbl_sale[[#This Row],[Delivery Date]]-tbl_sale[[#This Row],[Order Date]]<= 2,"Fast","Slow")),"Error") -> Pending | S22: =_xlfn.XLOOKUP(tbl_sale[[#This Row],[Region]],RegionGoals!$A$2:$A$6,RegionGoals!$B$2:$B$6, ,0) -> 97500 | T22: =_xlfn.XLOOKUP(tbl_sale[[#This Row],[Customer ID]],CustomerMaster!$A:$A,CustomerMaster!$C:$C,"NA",0) -> Prime | U22: =IF(tbl_sale[[#This Row],[Delivery Status]]="Cancelled",1,0) -> 0 | V22: =IF(tbl_sale[[#This Row],[Order ID]]<>"",1,0) -> 1 | W22: =IF(AND(tbl_sale[[#This Row],[Delivery Status]]="Delivered",tbl_sale[[#This Row],[Delivery Performance]]="Fast"),1,0) -> 0 | X22: =IF(tbl_sale[[#This Row],[Delivery Status]]="Delivered",1,0) -> 0
A23: ORD0022 | B23: 45239 | E23: =TEXT(tbl_sale[[#This Row],[Order Date]],"MMM") -> Nov | F23: =IF(D23<>"","Cancelled",IF(C23<>"","Delivered","In Transit")) -> In Transit | G23: CUST023 | H23: PROD012 | I23: West | J23: 46 | K23: 5 | L23: 230 | M23: PayPal | N23: USPS | O23: =_xlfn.XLOOKUP(tbl_sale[[#This Row],[Customer ID]],CustomerMaster!A:A,CustomerMaster!B:B,"NA",0) -> Charlotte Reed | P23: =_xlfn.XLOOKUP(tbl_sale[[#This Row],[Product ID]],ProductMaster!$A$2:$A$23,ProductMaster!$B$2:$B$23,"NA",0) -> Lamp | Q23: =_xlfn.XLOOKUP(tbl_sale[[#This Row],[Product ID]],ProductMaster!$A$2:$A$23,ProductMaster!$C$2:$C$23,"NA",0) -> Home | R23: =IFERROR(IF(tbl_sale[[#This Row],[Delivery Date]]="","Pending",IF(tbl_sale[[#This Row],[Delivery Date]]-tbl_sale[[#This Row],[Order Date]]<= 2,"Fast","Slow")),"Error") -> Pending | S23: =_xlfn.XLOOKUP(tbl_sale[[#This Row],[Region]],RegionGoals!$A$2:$A$6,RegionGoals!$B$2:$B$6, ,0) -> 90750 | T23: =_xlfn.XLOOKUP(tbl_sale[[#This Row],[Customer ID]],CustomerMaster!$A:$A,CustomerMaster!$C:$C,"NA",0) -> Individual | U23: =IF(tbl_sale[[#This Row],[Delivery Status]]="Cancelled",1,0) -> 0 | V23: =IF(tbl_sale[[#This Row],[Order ID]]<>"",1,0) -> 1 | W23: =IF(AND(tbl_sale[[#This Row],[Delivery Status]]="Delivered",tbl_sale[[#This Row],[Delivery Performance]]="Fast"),1,0) -> 0 | X23: =IF(tbl_sale[[#This Row],[Delivery Status]]="Delivered",1,0) -> 0
A24: ORD0023 | B24: 44970 | D24: 44971 | E24: =TEXT(tbl_sale[[#This Row],[Order Date]],"MMM") -> Feb | F24: =IF(D24<>"","Cancelled",IF(C24<>"","Delivered","In Transit")) -> Cancelled | G24: CUST016 | H24: PROD010 | I24: West | J24: 58 | K24: 3 | L24: 174 | M24: Amazon Pay | N24: Amazon Logistics | O24: =_xlfn.XLOOKUP(tbl_sale[[#This Row],[Customer ID]],CustomerMaster!A:A,CustomerMaster!B:B,"NA",0) -> Elijah Lewis | P24: =_xlfn.XLOOKUP(tbl_sale[[#This Row],[Product ID]],ProductMaster!$A$2:$A$23,ProductMaster!$B$2:$B$23,"NA",0) -> Jeans | Q24: =_xlfn.XLOOKUP(tbl_sale[[#This Row],[Product ID]],ProductMaster!$A$2:$A$23,ProductMaster!$C$2:$C$23,"NA",0) -> Fashion | R24: =IFERROR(IF(tbl_sale[[#This Row],[Delivery Date]]="","Pending",IF(tbl_sale[[#This Row],[Delivery Date]]-tbl_sale[[#This Row],[Order Date]]<= 2,"Fast","Slow")),"Error") -> Pending | S24: =_xlfn.XLOOKUP(tbl_sale[[#This Row],[Region]],RegionGoals!$A$2:$A$6,RegionGoals!$B$2:$B$6, ,0) -> 90750 | T24: =_xlfn.XLOOKUP(tbl_sale[[#This Row],[Customer ID]],CustomerMaster!$A:$A,CustomerMaster!$C:$C,"NA",0) -> Prime | U24: =IF(tbl_sale[[#This Row],[Delivery Status]]="Cancelled",1,0) -> 1 | V24: =IF(tbl_sale[[#This Row],[Order ID]]<>"",1,0) -> 1 | W24: =IF(AND(tbl_sale[[#This Row],[Delivery Status]]="Delivered",tbl_sale[[#This Row],[Delivery Performance]]="Fast"),1,0) -> 0 | X24: =IF(tbl_sale[[#This Row],[Delivery Status]]="Delivered",1,0) -> 0
A25: ORD0024 | B25: 45232 | C25: 45235 | E25: =TEXT(tbl_sale[[#This Row],[Order Date]],"MMM") -> Nov | F25: =IF(D25<>"","Cancelled",IF(C25<>"","Delivered","In Transit")) -> Delivered | G25: CUST028 | H25: PROD006 | I25: West | J25: 96 | K25: 5 | L25: 480 | M25: Amazon Pay | N25: Amazon Logistics | O25: =_xlfn.XLOOKUP(tbl_sale[[#This Row],[Customer ID]],CustomerMaster!A:A,CustomerMaster!B:B,"NA",0) -> Lily Bennett | P25: =_xlfn.XLOOKUP(tbl_sale[[#This Row],[Product ID]],ProductMaster!$A$2:$A$23,ProductMaster!$B$2:$B$23,"NA",0) -> Shoes | Q25: =_xlfn.XLOOKUP(tbl_sale[[#This Row],[Product ID]],ProductMaster!$A$2:$A$23,ProductMaster!$C$2:$C$23,"NA",0) -> Fashion | R25: =IFERROR(IF(tbl_sale[[#This Row],[Delivery Date]]="","Pending",IF(tbl_sale[[#This Row],[Delivery Date]]-tbl_sale[[#This Row],[Order Date]]<= 2,"Fast","Slow")),"Error") -> Slow | S25: =_xlfn.XLOOKUP(tbl_sale[[#This Row],[Region]],RegionGoals!$A$2:$A$6,RegionGoals!$B$2:$B$6, ,0) -> 90750 | T25: =_xlfn.XLOOKUP(tbl_sale[[#This Row],[Customer ID]],CustomerMaster!$A:$A,CustomerMaster!$C:$C,"NA",0) -> Business | U25: =IF(tbl_sale[[#This Row],[Delivery Status]]="Cancelled",1,0) -> 0 | V25: =IF(tbl_sale[[#This Row],[Order ID]]<>"",1,0) -> 1 | W25: =IF(AND(tbl_sale[[#This Row],[Delivery Status]]="Delivered",tbl_sale[[#This Row],[Delivery Performance]]="Fast"),1,0) -> 0 | X25: =IF(tbl_sale[[#This Row],[Delivery Status]]="Delivered",1,0) -> 1
A26: ORD0025 | B26: 45074 | C26: 45076 | E26: =TEXT(tbl_sale[[#This Row],[Order Date]],"MMM") -> May | F26: =IF(D26<>"","Cancelled",IF(C26<>"","Delivered","In Transit")) -> Delivered | G26: CUST040 | H26: PROD002 | I26: South | J26: 43 | K26: 1 | L26: 43 | M26: Debit Card | N26: Amazon Logistics | O26: =_xlfn.XLOOKUP(tbl_sale[[#This Row],[Customer ID]],CustomerMaster!A:A,CustomerMaster!B:B,"NA",0) -> Benjamin Clark | P26: =_xlfn.XLOOKUP(tbl_sale[[#This Row],[Product ID]],ProductMaster!$A$2:$A$23,ProductMaster!$B$2:$B$23,"NA",0) -> Action Figure | Q26: =_xlfn.XLOOKUP(tbl_sale[[#This Row],[Product ID]],ProductMaster!$A$2:$A$23,ProductMaster!$C$2:$C$23,"NA",0) -> Toys | R26: =IFERROR(IF(tbl_sale[[#This Row],[Delivery Date]]="","Pending",IF(tbl_sale[[#This Row],[Delivery Date]]-tbl_sale[[#This Row],[Order Date]]<= 2,"Fast","Slow")),"Error") -> Fast | S26: =_xlfn.XLOOKUP(tbl_sale[[#This Row],[Region]],RegionGoals!$A$2:$A$6,RegionGoals!$B$2:$B$6, ,0) -> 91500 | T26: =_xlfn.XLOOKUP(tbl_sale[[#This Row],[Customer ID]],CustomerMaster!$A:$A,CustomerMaster!$C:$C,"NA",0) -> Prime | U26: =IF(tbl_sale[[#This Row],[Delivery Status]]="Cancelled",1,0) -> 0 | V26: =IF(tbl_sale[[#This Row],[Order ID]]<>"",1,0) -> 1 | W26: =IF(AND(tbl_sale[[#This Row],[Delivery Status]]="Delivered",tbl_sale[[#This Row],[Delivery Performance]]="Fast"),1,0) -> 1 | X26: =IF(tbl_sale[[#This Row],[Delivery Status]]="Delivered",1,0) -> 1
A27: ORD0026 | B27: 45214 | C27: 45220 | E27: =TEXT(tbl_sale[[#This Row],[Order Date]],"MMM") -> Oct | F27: =IF(D27<>"","Cancelled",IF(C27<>"","Delivered","In Transit")) -> Delivered | G27: CUST027 | H27: PROD022 | I27: South | J27: 64 | K27: 4 | L27: 256 | M27: Debit Card | N27: USPS | O27: =_xlfn.XLOOKUP(tbl_sale[[#This Row],[Customer ID]],CustomerMaster!A:A,CustomerMaster!B:B,"NA",0) -> Hazel Brooks | P27: =_xlfn.XLOOKUP(tbl_sale[[#This Row],[Product ID]],ProductMaster!$A$2:$A$23,ProductMaster!$B$2:$B$23,"NA",0) -> Backpack | Q27: =_xlfn.XLOOKUP(tbl_sale[[#This Row],[Product ID]],ProductMaster!$A$2:$A$23,ProductMaster!$C$2:$C$23,"NA",0) -> Fashion | R27: =IFERROR(IF(tbl_sale[[#This Row],[Delivery Date]]="","Pending",IF(tbl_sale[[#This Row],[Delivery Date]]-tbl_sale[[#This Row],[Order Date]]<= 2,"Fast","Slow")),"Error") -> Slow | S27: =_xlfn.XLOOKUP(tbl_sale[[#This Row],[Region]],RegionGoals!$A$2:$A$6,RegionGoals!$B$2:$B$6, ,0) -> 91500 | T27: =_xlfn.XLOOKUP(tbl_sale[[#This Row],[Customer ID]],CustomerMaster!$A:$A,CustomerMaster!$C:$C,"NA",0) -> Individual | U27: =IF(tbl_sale[[#This Row],[Delivery Status]]="Cancelled",1,0) -> 0 | V27: =IF(tbl_sale[[#This Row],[Order ID]]<>"",1,0) -> 1 | W27: =IF(AND(tbl_sale[[#This Row],[Delivery Status]]="Delivered",tbl_sale[[#This Row],[Delivery Performance]]="Fast"),1,0) -> 0 | X27: =IF(tbl_sale[[#This Row],[Delivery Status]]="Delivered",1,0) -> 1
A28: ORD0027 | B28: 44942 | E28: =TEXT(tbl_sale[[#This Row],[Order Date]],"MMM") -> Jan | F28: =IF(D28<>"","Cancelled",IF(C28<>"","Delivered","In Transit")) -> In Transit | G28: CUST018 | H28: PROD008 | I28: South | J28: 70 | K28: 2 | L28: 140 | M28: Amazon Pay | N28: Amazon Logistics | O28: =_xlfn.XLOOKUP(tbl_sale[[#This Row],[Customer ID]],CustomerMaster!A:A,CustomerMaster!B:B,"NA",0) -> Grace Scott | P28: =_xlfn.XLOOKUP(tbl_sale[[#This Row],[Product ID]],ProductMaster!$A$2:$A$23,ProductMaster!$B$2:$B$23,"NA",0) -> Textbook | Q28: =_xlfn.XLOOKUP(tbl_sale[[#This Row],[Product ID]],ProductMaster!$A$2:$A$23,ProductMaster!$C$2:$C$23,"NA",0) -> Books | R28: =IFERROR(IF(tbl_sale[[#This Row],[Delivery Date]]="","Pending",IF(tbl_sale[[#This Row],[Delivery Date]]-tbl_sale[[#This Row],[Order Date]]<= 2,"Fast","Slow")),"Error") -> Pending | S28: =_xlfn.XLOOKUP(tbl_sale[[#This Row],[Region]],RegionGoals!$A$2:$A$6,RegionGoals!$B$2:$B$6, ,0) -> 91500 | T28: =_xlfn.XLOOKUP(tbl_sale[[#This Row],[Customer ID]],CustomerMaster!$A:$A,CustomerMaster!$C:$C,"NA",0) -> Individual | U28: =IF(tbl_sale[[#This Row],[Delivery Status]]="Cancelled",1,0) -> 0 | V28: =IF(tbl_sale[[#This Row],[Order ID]]<>"",1,0) -> 1 | W28: =IF(AND(tbl_sale[[#This Row],[Delivery Status]]="Delivered",tbl_sale[[#This Row],[Delivery Performance]]="Fast"),1,0) -> 0 | X28: =IF(tbl_sale[[#This Row],[Delivery Status]]="Delivered",1,0) -> 0
A29: ORD0028 | B29: 45208 | E29: =TEXT(tbl_sale[[#This Row],[Order Date]],"MMM") -> Oct | F29: =IF(D29<>"","Cancelled",IF(C29<>"","Delivered","In Transit")) -> In Transit | G29: CUST018 | H29: PROD018 | I29: Central | J29: 97 | K29: 3 | L29: 291 | M29: Credit Card | N29: Amazon Logistics | O29: =_xlfn.XLOOKUP(tbl_sale[[#This Row],[Customer ID]],CustomerMaster!A:A,CustomerMaster!B:B,"NA",0) -> Grace Scott | P29: =_xlfn.XLOOKUP(tbl_sale[[#This Row],[Product ID]],ProductMaster!$A$2:$A$23,ProductMaster!$B$2:$B$23,"NA",0) -> Doll House | Q29: =_xlfn.XLOOKUP(tbl_sale[[#This Row],[Product ID]],ProductMaster!$A$2:$A$23,ProductMaster!$C$2:$C$23,"NA",0) -> Toys | R29: =IFERROR(IF(tbl_sale[[#This Row],[Delivery Date]]="","Pending",IF(tbl_sale[[#This Row],[Delivery Date]]-tbl_sale[[#This Row],[Order Date]]<= 2,"Fast","Slow")),"Error") -> Pending | S29: =_xlfn.XLOOKUP(tbl_sale[[#This Row],[Region]],RegionGoals!$A$2:$A$6,RegionGoals!$B$2:$B$6, ,0) -> 97500 | T29: =_xlfn.XLOOKUP(tbl_sale[[#This Row],[Customer ID]],CustomerMaster!$A:$A,CustomerMaster!$C:$C,"NA",0) -> Individual | U29: =IF(tbl_sale[[#This Row],[Delivery Status]]="Cancelled",1,0) -> 0 | V29: =IF(tbl_sale[[#This Row],[Order ID]]<>"",1,0) -> 1 | W29: =IF(AND(tbl_sale[[#This Row],[Delivery Status]]="Delivered",tbl_sale[[#This Row],[Delivery Performance]]="Fast"),1,0) -> 0 | X29: =IF(tbl_sale[[#This Row],[Delivery Status]]="Delivered",1,0) -> 0
A30: ORD0029 | B30: 45206 | D30: 45209 | E30: =TEXT(tbl_sale[[#This Row],[Order Date]],"MMM") -> Oct | F30: =IF(D30<>"","Cancelled",IF(C30<>"","Delivered","In Transit")) -> Cancelled | G30: CUST007 | H30: PROD021 | I30: East | J30: 37 | K30: 3 | L30: 111 | M30: Apple Pay | N30: DHL | O30: =_xlfn.XLOOKUP(tbl_sale[[#This Row],[Customer ID]],CustomerMaster!A:A,CustomerMaster!B:B,"NA",0) -> Liam Walker | P30: =_xlfn.XLOOKUP(tbl_sale[[#This Row],[Product ID]],ProductMaster!$A$2:$A$23,ProductMaster!$B$2:$B$23,"NA",0) -> Wall Clock | Q30: =_xlfn.XLOOKUP(tbl_sale[[#This Row],[Product ID]],ProductMaster!$A$2:$A$23,ProductMaster!$C$2:$C$23,"NA",0) -> Home | R30: =IFERROR(IF(tbl_sale[[#This Row],[Delivery Date]]="","Pending",IF(tbl_sale[[#This Row],[Delivery Date]]-tbl_sale[[#This Row],[Order Date]]<= 2,"Fast","Slow")),"Error") -> Pending | S30: =_xlfn.XLOOKUP(tbl_sale[[#This Row],[Region]],RegionGoals!$A$2:$A$6,RegionGoals!$B$2:$B$6, ,0) -> 50500 | T30: =_xlfn.XLOOKUP(tbl_sale[[#This Row],[Customer ID]],CustomerMaster!$A:$A,CustomerMaster!$C:$C,"NA",0) -> Prime | U30: =IF(tbl_sale[[#This Row],[Delivery Status]]="Cancelled",1,0) -> 1 | V30: =IF(tbl_sale[[#This Row],[Order ID]]<>"",1,0) -> 1 | W30: =IF(AND(tbl_sale[[#This Row],[Delivery Status]]="Delivered",tbl_sale[[#This Row],[Delivery Performance]]="Fast"),1,0) -> 0 | X30: =IF(tbl_sale[[#This Row],[Delivery Status]]="Delivered",1,0) -> 0
A31: ORD0030 | B31: 44971 | E31: =TEXT(tbl_sale[[#This Row],[Order Date]],"MMM") -> Feb | F31: =IF(D31<>"","Cancelled",IF(C31<>"","Delivered","In Transit")) -> In Transit | G31: CUST008 | H31: PROD008 | I31: North | J31: 69 | K31: 5 | L31: 345 | M31: Amazon Pay | N31: Amazon Logistics | O31: =_xlfn.XLOOKUP(tbl_sale[[#This Row],[Customer ID]],CustomerMaster!A:A,CustomerMaster!B:B,"NA",0) -> Harper Young | P31: =_xlfn.XLOOKUP(tbl_sale[[#This Row],[Product ID]],ProductMaster!$A$2:$A$23,ProductMaster!$B$2:$B$23,"NA",0) -> Textbook | Q31: =_xlfn.XLOOKUP(tbl_sale[[#This Row],[Product ID]],ProductMaster!$A$2:$A$23,ProductMaster!$C$2:$C$23,"NA",0) -> Books | R31: =IFERROR(IF(tbl_sale[[#This Row],[Delivery Date]]="","Pending",IF(tbl_sale[[#This Row],[Delivery Date]]-tbl_sale[[#This Row],[Order Date]]<= 2,"Fast","Slow")),"Error") -> Pending | S31: =_xlfn.XLOOKUP(tbl_sale[[#This Row],[Region]],RegionGoals!$A$2:$A$6,RegionGoals!$B$2:$B$6, ,0) -> 105000 | T31: =_xlfn.XLOOKUP(tbl_sale[[#This Row],[Customer ID]],CustomerMaster!$A:$A,CustomerMaster!$C:$C,"NA",0) -> Business | U31: =IF(tbl_sale[[#This Row],[Delivery Status]]="Cancelled",1,0) -> 0 | V31: =IF(tbl_sale[[#This Row],[Order ID]]<>"",1,0) -> 1 | W31: =IF(AND(tbl_sale[[#This Row],[Delivery Status]]="Delivered",tbl_sale[[#This Row],[Delivery Performance]]="Fast"),1,0) -> 0 | X31: =IF(tbl_sale[[#This Row],[Delivery Status]]="Delivered",1,0) -> 0
A32: ORD0031 | B32: 45011 | E32: =TEXT(tbl_sale[[#This Row],[Order Date]],"MMM") -> Mar | F32: =IF(D32<>"","Cancelled",IF(C32<>"","Delivered","In Transit")) -> In Transit | G32: CUST014 | H32: PROD002 | I32: North | J32: 42 | K32: 5 | L32: 210 | M32: Amazon Pay | N32: UPS | O32: =_xlfn.XLOOKUP(tbl_sale[[#This Row],[Customer ID]],CustomerMaster!A:A,CustomerMaster!B:B,"NA",0) -> Harper Young | P32: =_xlfn.XLOOKUP(tbl_sale[[#This Row],[Product ID]],ProductMaster!$A$2:$A$23,ProductMaster!$B$2:$B$23,"NA",0) -> Action Figure | Q32: =_xlfn.XLOOKUP(tbl_sale[[#This Row],[Product ID]],ProductMaster!$A$2:$A$23,ProductMaster!$C$2:$C$23,"NA",0) -> Toys | R32: =IFERROR(IF(tbl_sale[[#This Row],[Delivery Date]]="","Pending",IF(tbl_sale[[#This Row],[Delivery Date]]-tbl_sale[[#This Row],[Order Date]]<= 2,"Fast","Slow")),"Error") -> Pending | S32: =_xlfn.XLOOKUP(tbl_sale[[#This Row],[Region]],RegionGoals!$A$2:$A$6,RegionGoals!$B$2:$B$6, ,0) -> 105000 | T32: =_xlfn.XLOOKUP(tbl_sale[[#This Row],[Customer ID]],CustomerMaster!$A:$A,CustomerMaster!$C:$C,"NA",0) -> Individual | U32: =IF(tbl_sale[[#This Row],[Delivery Status]]="Cancelled",1,0) -> 0 | V32: =IF(tbl_sale[[#This Row],[Order ID]]<>"",1,0) -> 1 | W32: =IF(AND(tbl_sale[[#This Row],[Delivery Status]]="Delivered",tbl_sale[[#This Row],[Delivery Performance]]="Fast"),1,0) -> 0 | X32: =IF(tbl_sale[[#This Row],[Delivery Status]]="Delivered",1,0) -> 0
A33: ORD0032 | B33: 45092 | D33: 45099 | E33: =TEXT(tbl_sale[[#This Row],[Order Date]],"MMM") -> Jun | F33: =IF(D33<>"","Cancelled",IF(C33<>"","Delivered","In Transit")) -> Cancelled | G33: CUST037 | H33: PROD009 | I33: East | J33: 11 | K33: 5 | L33: 55 | M33: Debit Card | N33: FedEx | O33: =_xlfn.XLOOKUP(tbl_sale[[#This Row],[Customer ID]],CustomerMaster!A:A,CustomerMaster!B:B,"NA",0) -> Emily Johnson | P33: =_xlfn.XLOOKUP(tbl_sale[[#This Row],[Product ID]],ProductMaster!$A$2:$A$23,ProductMaster!$B$2:$B$23,"NA",0) -> Magazine | Q33: =_xlfn.XLOOKUP(tbl_sale[[#This Row],[Product ID]],ProductMaster!$A$2:$A$23,ProductMaster!$C$2:$C$23,"NA",0) -> Books | R33: =IFERROR(IF(tbl_sale[[#This Row],[Delivery Date]]="","Pending",IF(tbl_sale[[#This Row],[Delivery Date]]-tbl_sale[[#This Row],[Order Date]]<= 2,"Fast","Slow")),"Error") -> Pending | S33: =_xlfn.XLOOKUP(tbl_sale[[#This Row],[Region]],RegionGoals!$A$2:$A$6,RegionGoals!$B$2:$B$6, ,0) -> 50500 | T33: =_xlfn.XLOOKUP(tbl_sale[[#This Row],[Customer ID]],CustomerMaster!$A:$A,CustomerMaster!$C:$C,"NA",0) -> Individual | U33: =IF(tbl_sale[[#This Row],[Delivery Status]]="Cancelled",1,0) -> 1 | V33: =IF(tbl_sale[[#This Row],[Order ID]]<>"",1,0) -> 1 | W33: =IF(AND(tbl_sale[[#This Row],[Delivery Status]]="Delivered",tbl_sale[[#This Row],[Delivery Performance]]="Fast"),1,0) -> 0 | X33: =IF(tbl_sale[[#This Row],[Delivery Status]]="Delivered",1,0) -> 0
A34: ORD0033 | B34: 45068 | C34: 45069 | E34: =TEXT(tbl_sale[[#This Row],[Order Date]],"MMM") -> May | F34: =IF(D34<>"","Cancelled",IF(C34<>"","Delivered","In Transit")) -> Delivered | G34: CUST016 | H34: PROD005 | I34: South | J34: 27 | K34: 2 | L34: 54 | M34: Apple Pay | N34: USPS | O34: =_xlfn.XLOOKUP(tbl_sale[[#This Row],[Customer ID]],CustomerMaster!A:A,CustomerMaster!B:B,"NA",0) -> Elijah Lewis | P34: =_xlfn.XLOOKUP(tbl_sale[[#This Row],[Product ID]],ProductMaster!$A$2:$A$23,ProductMaster!$B$2:$B$23,"NA",0) -> T-Shirt | Q34: =_xlfn.XLOOKUP(tbl_sale[[#This Row],[Product ID]],ProductMaster!$A$2:$A$23,ProductMaster!$C$2:$C$23,"NA",0) -> Fashion | R34: =IFERROR(IF(tbl_sale[[#This Row],[Delivery Date]]="","Pending",IF(tbl_sale[[#This Row],[Delivery Date]]-tbl_sale[[#This Row],[Order Date]]<= 2,"Fast","Slow")),"Error") -> Fast | S34: =_xlfn.XLOOKUP(tbl_sale[[#This Row],[Region]],RegionGoals!$A$2:$A$6,RegionGoals!$B$2:$B$6, ,0) -> 91500 | T34: =_xlfn.XLOOKUP(tbl_sale[[#This Row],[Customer ID]],CustomerMaster!$A:$A,CustomerMaster!$C:$C,"NA",0) -> Prime | U34: =IF(tbl_sale[[#This Row],[Delivery Status]]="Cancelled",1,0) -> 0 | V34: =IF(tbl_sale[[#This Row],[Order ID]]<>"",1,0) -> 1 | W34: =IF(AND(tbl_sale[[#This Row],[Delivery Status]]="Delivered",tbl_sale[[#This Row],[Delivery Performance]]="Fast"),1,0) -> 1 | X34: =IF(tbl_sale[[#This Row],[Delivery Status]]="Delivered",1,0) -> 1
A35: ORD0034 | B35: 45250 | E35: =TEXT(tbl_sale[[#This Row],[Order Date]],"MMM") -> Nov | F35: =IF(D35<>"","Cancelled",IF(C35<>"","Delivered","In Transit")) -> In Transit | G35: CUST025 | H35: PROD015 | I35: South | J35: 21 | K35: 1 | L35: 21 | M35: Amazon Pay | N35: DHL | O35: =_xlfn.XLOOKUP(tbl_sale[[#This Row],[Customer ID]],CustomerMaster!A:A,CustomerMaster!B:B,"NA",0) -> Emma King | P35: =_xlfn.XLOOKUP(tbl_sale[[#This Row],[Product ID]],ProductMaster!$A$2:$A$23,ProductMaster!$B$2:$B$23,"NA",0) -> Novel | Q35: =_xlfn.XLOOKUP(tbl_sale[[#This Row],[Product ID]],ProductMaster!$A$2:$A$23,ProductMaster!$C$2:$C$23,"NA",0) -> Books | R35: =IFERROR(IF(tbl_sale[[#This Row],[Delivery Date]]="","Pending",IF(tbl_sale[[#This Row],[Delivery Date]]-tbl_sale[[#This Row],[Order Date]]<= 2,"Fast","Slow")),"Error") -> Pending | S35: =_xlfn.XLOOKUP(tbl_sale[[#This Row],[Region]],RegionGoals!$A$2:$A$6,RegionGoals!$B$2:$B$6, ,0) -> 91500 | T35: =_xlfn.XLOOKUP(tbl_sale[[#This Row],[Customer ID]],CustomerMaster!$A:$A,CustomerMaster!$C:$C,"NA",0) -> Individual | U35: =IF(tbl_sale[[#This Row],[Delivery Status]]="Cancelled",1,0) -> 0 | V35: =IF(tbl_sale[[#This Row],[Order ID]]<>"",1,0) -> 1 | W35: =IF(AND(tbl_sale[[#This Row],[Delivery Status]]="Delivered",tbl_sale[[#This Row],[Delivery Performance]]="Fast"),1,0) -> 0 | X35: =IF(tbl_sale[[#This Row],[Delivery Status]]="Delivered",1,0) -> 0
A36: ORD0035 | B36: 45282 | C36: 45286 | E36: =TEXT(tbl_sale[[#This Row],[Order Date]],"MMM") -> Dec | F36: =IF(D36<>"","Cancelled",IF(C36<>"","Delivered","In Transit")) -> Delivered | G36: CUST032 | H36: PROD011 | I36: South | J36: 172 | K36: 1 | L36: 172 | M36: PayPal | N36: USPS | O36: =_xlfn.XLOOKUP(tbl_sale[[#This Row],[Customer ID]],CustomerMaster!A:A,CustomerMaster!B:B,"NA",0) -> Luke Gray | P36: =_xlfn.XLOOKUP(tbl_sale[[#This Row],[Product ID]],ProductMaster!$A$2:$A$23,ProductMaster!$B$2:$B$23,"NA",0) -> Headphones | Q36: =_xlfn.XLOOKUP(tbl_sale[[#This Row],[Product ID]],ProductMaster!$A$2:$A$23,ProductMaster!$C$2:$C$23,"NA",0) -> Electronics | R36: =IFERROR(IF(tbl_sale[[#This Row],[Delivery Date]]="","Pending",IF(tbl_sale[[#This Row],[Delivery Date]]-tbl_sale[[#This Row],[Order Date]]<= 2,"Fast","Slow")),"Error") -> Slow | S36: =_xlfn.XLOOKUP(tbl_sale[[#This Row],[Region]],RegionGoals!$A$2:$A$6,RegionGoals!$B$2:$B$6, ,0) -> 91500 | T36: =_xlfn.XLOOKUP(tbl_sale[[#This Row],[Customer ID]],CustomerMaster!$A:$A,CustomerMaster!$C:$C,"NA",0) -> Business | U36: =IF(tbl_sale[[#This Row],[Delivery Status]]="Cancelled",1,0) -> 0 | V36: =IF(tbl_sale[[#This Row],[Order ID]]<>"",1,0) -> 1 | W36: =IF(AND(tbl_sale[[#This Row],[Delivery Status]]="Delivered",tbl_sale[[#This Row],[Delivery Performance]]="Fast"),1,0) -> 0 | X36: =IF(tbl_sale[[#This Row],[Delivery Status]]="Delivered",1,0) -> 1
A37: ORD0036 | B37: 45130 | E37: =TEXT(tbl_sale[[#This Row],[Order Date]],"MMM") -> Jul | F37: =IF(D37<>"","Cancelled",IF(C37<>"","Delivered","In Transit")) -> In Transit | G37: CUST014 | H37: PROD016 | I37: North | J37: 212 | K37: 3 | L37: 636 | M37: Amazon Pay | N37: UPS | O37: =_xlfn.XLOOKUP(tbl_sale[[#This Row],[Customer ID]],CustomerMaster!A:A,CustomerMaster!B:B,"NA",0) -> Harper Young | P37: =_xlfn.XLOOKUP(tbl_sale[[#This Row],[Product ID]],ProductMaster!$A$2:$A$23,ProductMaster!$B$2:$B$23,"NA",0) -> Cookware Set Pro | Q37: =_xlfn.XLOOKUP(tbl_sale[[#This Row],[Product ID]],ProductMaster!$A$2:$A$23,ProductMaster!$C$2:$C$23,"NA",0) -> Home | R37: =IFERROR(IF(tbl_sale[[#This Row],[Delivery Date]]="","Pending",IF(tbl_sale[[#This Row],[Delivery Date]]-tbl_sale[[#This Row],[Order Date]]<= 2,"Fast","Slow")),"Error") -> Pending | S37: =_xlfn.XLOOKUP(tbl_sale[[#This Row],[Region]],RegionGoals!$A$2:$A$6,RegionGoals!$B$2:$B$6, ,0) -> 105000 | T37: =_xlfn.XLOOKUP(tbl_sale[[#This Row],[Customer ID]],CustomerMaster!$A:$A,CustomerMaster!$C:$C,"NA",0) -> Individual | U37: =IF(tbl_sale[[#This Row],[Delivery Status]]="Cancelled",1,0) -> 0 | V37: =IF(tbl_sale[[#This Row],[Order ID]]<>"",1,0) -> 1 | W37: =IF(AND(tbl_sale[[#This Row],[Delivery Status]]="Delivered",tbl_sale[[#This Row],[Delivery Performance]]="Fast"),1,0) -> 0 | X37: =IF(tbl_sale[[#This Row],[Delivery Status]]="Delivered",1,0) -> 0
A38: ORD0037 | B38: 45216 | C38: 45221 | E38: =TEXT(tbl_sale[[#This Row],[Order Date]],"MMM") -> Oct | F38: =IF(D38<>"","Cancelled",IF(C38<>"","Delivered","In Transit")) -> Delivered | G38: CUST044 | H38: PROD002 | I38: East | J38: 41 | K38: 4 | L38: 164 | M38: Credit Card | N38: Amazon Logistics | O38: =_xlfn.XLOOKUP(tbl_sale[[#This Row],[Customer ID]],CustomerMaster!A:A,CustomerMaster!B:B,"NA",0) -> Grace Ward | P38: =_xlfn.XLOOKUP(tbl_sale[[#This Row],[Product ID]],ProductMaster!$A$2:$A$23,ProductMaster!$B$2:$B$23,"NA",0) -> Action Figure | Q38: =_xlfn.XLOOKUP(tbl_sale[[#This Row],[Product ID]],ProductMaster!$A$2:$A$23,ProductMaster!$C$2:$C$23,"NA",0) -> Toys | R38: =IFERROR(IF(tbl_sale[[#This Row],[Delivery Date]]="","Pending",IF(tbl_sale[[#This Row],[Delivery Date]]-tbl_sale[[#This Row],[Order Date]]<= 2,"Fast","Slow")),"Error") -> Slow | S38: =_xlfn.XLOOKUP(tbl_sale[[#This Row],[Region]],RegionGoals!$A$2:$A$6,RegionGoals!$B$2:$B$6, ,0) -> 50500 | T38: =_xlfn.XLOOKUP(tbl_sale[[#This Row],[Customer ID]],CustomerMaster!$A:$A,CustomerMaster!$C:$C,"NA",0) -> Business | U38: =IF(tbl_sale[[#This Row],[Delivery Status]]="Cancelled",1,0) -> 0 | V38: =IF(tbl_sale[[#This Row],[Order ID]]<>"",1,0) -> 1 | W38: =IF(AND(tbl_sale[[#This Row],[Delivery Status]]="Delivered",tbl_sale[[#This Row],[Delivery Performance]]="Fast"),1,0) -> 0 | X38: =IF(tbl_sale[[#This Row],[Delivery Status]]="Delivered",1,0) -> 1
A39: ORD0038 | B39: 45160 | D39: 45162 | E39: =TEXT(tbl_sale[[#This Row],[Order Date]],"MMM") -> Aug | F39: =IF(D39<>"","Cancelled",IF(C39<>"","Delivered","In Transit")) -> Cancelled | G39: CUST028 | H39: PROD007 | I39: North | J39: 32 | K39: 2 | L39: 64 | M39: Debit Card | N39: FedEx | O39: =_xlfn.XLOOKUP(tbl_sale[[#This Row],[Customer ID]],CustomerMaster!A:A,CustomerMaster!B:B,"NA",0) -> Lily Bennett | P39: =_xlfn.XLOOKUP(tbl_sale[[#This Row],[Product ID]],ProductMaster!$A$2:$A$23,ProductMaster!$B$2:$B$23,"NA",0) -> Puzzle | Q39: =_xlfn.XLOOKUP(tbl_sale[[#This Row],[Product ID]],ProductMaster!$A$2:$A$23,ProductMaster!$C$2:$C$23,"NA",0) -> Toys | R39: =IFERROR(IF(tbl_sale[[#This Row],[Delivery Date]]="","Pending",IF(tbl_sale[[#This Row],[Delivery Date]]-tbl_sale[[#This Row],[Order Date]]<= 2,"Fast","Slow")),"Error") -> Pending | S39: =_xlfn.XLOOKUP(tbl_sale[[#This Row],[Region]],RegionGoals!$A$2:$A$6,RegionGoals!$B$2:$B$6, ,0) -> 105000 | T39: =_xlfn.XLOOKUP(tbl_sale[[#This Row],[Customer ID]],CustomerMaster!$A:$A,CustomerMaster!$C:$C,"NA",0) -> Business | U39: =IF(tbl_sale[[#This Row],[Delivery Status]]="Cancelled",1,0) -> 1 | V39: =IF(tbl_sale[[#This Row],[Order ID]]<>"",1,0) -> 1 | W39: =IF(AND(tbl_sale[[#This Row],[Delivery Status]]="Delivered",tbl_sale[[#This Row],[Delivery Performance]]="Fast"),1,0) -> 0 | X39: =IF(tbl_sale[[#This Row],[Delivery Status]]="Delivered",1,0) -> 0
A40: ORD0039 | B40: 45262 | E40: =TEXT(tbl_sale[[#This Row],[Order Date]],"MMM") -> Dec | F40: =IF(D40<>"","Cancelled",IF(C40<>"","Delivered","In Transit")) -> In Transit | G40: CUST024 | H40: PROD022 | I40: East | J40: 66 | K40: 2 | L40: 132 | M40: Apple Pay | N40: DHL | O40: =_xlfn.XLOOKUP(tbl_sale[[#This Row],[Customer ID]],CustomerMaster!A:A,CustomerMaster!B:B,"NA",0) -> Scarlett Murphy | P40: =_xlfn.XLOOKUP(tbl_sale[[#This Row],[Product ID]],ProductMaster!$A$2:$A$23,ProductMaster!$B$2:$B$23,"NA",0) -> Backpack | Q40: =_xlfn.XLOOKUP(tbl_sale[[#This Row],[Product ID]],ProductMaster!$A$2:$A$23,ProductMaster!$C$2:$C$23,"NA",0) -> Fashion | R40: =IFERROR(IF(tbl_sale[[#This Row],[Delivery Date]]="","Pending",IF(tbl_sale[[#This Row],[Delivery Date]]-tbl_sale[[#This Row],[Order Date]]<= 2,"Fast","Slow")),"Error") -> Pending | S40: =_xlfn.XLOOKUP(tbl_sale[[#This Row],[Region]],RegionGoals!$A$2:$A$6,RegionGoals!$B$2:$B$6, ,0) -> 50500 | T40: =_xlfn.XLOOKUP(tbl_sale[[#This Row],[Customer ID]],CustomerMaster!$A:$A,CustomerMaster!$C:$C,"NA",0) -> Business | U40: =IF(tbl_sale[[#This Row],[Delivery Status]]="Cancelled",1,0) -> 0 | V40: =IF(tbl_sale[[#This Row],[Order ID]]<>"",1,0) -> 1 | W40: =IF(AND(tbl_sale[[#This Row],[Delivery Status]]="Delivered",tbl_sale[[#This Row],[Delivery Performance]]="Fast"),1,0) -> 0 | X40: =IF(tbl_sale[[#This Row],[Delivery Status]]="Delivered",1,0) -> 0
...

Sheet ProductMaster
A1: Product ID | B1: Product Name | C1: Category | D1: Cost Price | E1: Description
A2: PROD001 | B2: Smartphone | C2: Electronics | D2: 749 | E2: Latest model with 5G, dual SIM, and OLED display
A3: PROD002 | B3: Action Figure | C3: Toys | D3: 39 | E3: Collectible superhero action figure for ages 8+
A4: PROD003 | B4: Cookware Set | C4: Home | D4: 129 | E4: Non-stick 5-piece cookware set for daily use
A5: PROD004 | B5: Leg Set | C5: Toys | D5: 59 | E5: 300-piece creative building block toy set
A6: PROD005 | B6: T-Shirt | C6: Fashion | D6: 25 | E6: Cotton t-shirt, available in multiple colors
A7: PROD006 | B7: Shoes | C7: Fashion | D7: 89 | E7: Casual wear shoes for men and women
A8: PROD007 | B8: Puzzle | C8: Toys | D8: 29 | E8: 1000-piece jigsaw puzzle
A9: PROD008 | B9: Textbook | C9: Books | D9: 65 | E9: University-level textbook on computer science
A10: PROD009 | B10: Magazine | C10: Books | D10: 10 | E10: Monthly lifestyle magazine
A11: PROD010 | B11: Jeans | C11: Fashion | D11: 55 | E11: Slim fit denim jeans with stretch
A12: PROD011 | B12: Headphones | C12: Electronics | D12: 159 | E12: Wireless noise-cancelling over-ear headphones
A13: PROD012 | B13: Lamp | C13: Home | D13: 42 | E13: LED desk lamp with dimmable light
... A23: PROD022 | B23: Backpack | C23: Fashion | D23: 60 | E23: Waterproof backpack with laptop compartment

Sheet RegionGoals
A1: Region | B1: Sales Target
A2: Central | B2: 97500
A3: East | B3: 50500
A4: North | B4: 105000
A5: South | B5: 91500
A6: West | B6: 90750

Sheet CustomerMaster
A1: Customer ID | B1: Customer Name | C1: Customer Type | D1: City | E1: State
A2: CUST001 | B2: James Miller | C2: Business | D2: New York | E2: New York
A3: CUST002 | B3: Emily Johnson | C3: Prime | D3: Seattle | E3: Washington
A4: CUST003 | B4: Ethan Davis | C4: Prime | D4: Austin | E4: Texas
A5: CUST004 | B5: Noah Wilson | C5: Prime | D5: San Francisco | E5: California
A6: CUST005 | B6: Olivia Martinez | C6: Prime | D6: Seattle | E6: Washington
A7: CUST006 | B7: Ava Robinson | C7: Prime | D7: Chicago | E7: Illinois
A8: CUST007 | B8: Liam Walker | C8: Prime | D8: San Francisco | E8: California
A9: CUST008 | B9: Harper Young | C9: Business | D9: Dallas | E9: Texas
A10: CUST009 | B10: Jackson Allen | C10: Business | D10: Seattle | E10: Washington
A11: CUST010 | B11: Charlotte Harris | C11: Prime | D11: Chicago | E11: Illinois
A12: CUST011 | B12: Mason Hall | C12: Business | D12: Miami | E12: Florida
... A50: CUST049 | B50: Hazel Gray | C50: Business | D50: Chicago | E50: Illinois
